Workbook

Sheet Dashboard
B1: EMBASSY OUTREACH - LEADERSHIP DASHBOARD
B3: ="Status as at "&TEXT(Analysis!B3,"dd mmm yyyy")&" | Source: cleaned Embassy Outreach Database ("&COUNTA(Clean_Data!A2:A500)&" embassies) | Illustrative sample data" -> Status as at 05 Oct 2026 | Source: cleaned Embassy Outreach Database (84 embassies) | Illustrative sample data
B5: TOTAL EMBASSIES | E5: CONTACTED | H5: FULLY ENGAGED | K5: LIVE PIPELINE | N5: OVERDUE FOLLOW-UPS | Q5: STALE (NO CONTACT)
B6: =COUNTA(Clean_Data!$A$2:$A$500) -> 84 | E6: =COUNTA(Clean_Data!$A$2:$A$500)-Analysis!B9 -> 74 | H6: =Analysis!B13 -> 19 | K6: =SUM(Clean_Data!Q2:Q500) -> 59 | N6: =SUM(Clean_Data!S2:S500) -> 30 | Q6: =SUM(Clean_Data!T2:T500) -> 13
B7: ="across "&COUNTA(Lists!C2:C7)&" regions" -> across 6 regions | E7: =TEXT(IF(B6=0,0,E6/B6),"0%")&" of all embassies" -> 88% of all embassies | H7: =TEXT(IF(E6=0,0,H6/E6),"0%")&" of contacted" -> 26% of contacted | K7: ="initial, discussion, meeting, engaged" -> initial, discussion, meeting, engaged | N7: =TEXT(IF(K6=0,0,N6/K6),"0%")&" of live pipeline" -> 51% of live pipeline | Q7: ="live, no contact "&Analysis!B4&"+ days" -> live, no contact 90+ days
B9: KEY INSIGHTS
B10: ="Reach: "&E6&" of "&B6&" embassies ("&TEXT(E6/B6,"0%")&") have been contacted; "&H6&" are fully engaged ("&TEXT(H6/B6,"0%")&" of all embassies) and "&Analysis!B9&" have not been approached yet." -> Reach: 74 of 84 embassies (88%) have been contacted; 19 are fully engaged (23% of all embassies) and 10 have not been approached yet.
B11: ="Regions: highest engagement rate is "&INDEX(Analysis!$A$28:$A$33,MATCH(MAX(Analysis!$J$28:$J$33),Analysis!$J$28:$J$33,0))&" ("&TEXT(MAX(Analysis!$J$28:$J$33),"0%")&"); lowest is "&INDEX(Analysis!$A$28:$A$33,MATCH(MIN(Analysis!$J$28:$J$33),Analysis!$J$28:$J$33,0))&" ("&TEXT(MIN(Analysis!$J$28:$J$33),"0%")&"). Overall: "&TEXT(Analysis!J34,"0%")&"." -> Regions: highest engagement rate is Sub-Saharan Africa (36%); lowest is South & Central Asia (13%). Overall: 23%.
B12: ="Follow-up discipline: "&N6&" of "&K6&" live embassies ("&TEXT(IF(K6=0,0,N6/K6),"0%")&") have an overdue follow-up and "&Q6&" have had no contact for "&Analysis!B4&"+ days - these need action first (see priority list)." -> Follow-up discipline: 30 of 59 live embassies (51%) have an overdue follow-up and 13 have had no contact for 90+ days - these need action first (see priority list).
B13: ="Ownership & data: "&Analysis!B45&" embassies have no assigned owner; "&TEXT('Data Quality Review'!E5,"0%")&" of raw records were free of data-quality issues - see the Data Quality Review sheet." -> Ownership & data: 8 embassies have no assigned owner; 21% of raw records were free of data-quality issues - see the Data Quality Review sheet.
B15: PIPELINE & ENGAGEMENT
B32: REGIONAL & TEAM VIEW
B66: REGIONAL SCORECARD
B67: Region | F67: Embassies | G67: Contacted | H67: Engaged | I67: Engaged % | J67: High Engage-ment | K67: Avg Interact-ions | L67: Overdue | M67: Stale | N67: No Owner | O67: Not Started | P67: Assessment
B68: =Analysis!A28 -> Europe | F68: =Analysis!B28 -> 20 | G68: =Analysis!P28 -> 16 | H68: =Analysis!G28 -> 3 | I68: =Analysis!J28 -> 0.15 | J68: =Analysis!K28 -> 3 | K68: =Analysis!L28 -> 6.2142857 | L68: =Analysis!M28 -> 6 | M68: =Analysis!N28 -> 4 | N68: =Analysis!O28 -> 1 | O68: =Analysis!C28 -> 4 | P68: =IF(I68<$I$74,"Below average engagement",IF(L68+M68>=3,"Engaged but needs follow-up","On track")) -> Below average engagement
B69: =Analysis!A29 -> Asia-Pacific | F69: =Analysis!B29 -> 14 | G69: =Analysis!P29 -> 13 | H69: =Analysis!G29 -> 3 | I69: =Analysis!J29 -> 0.21428571 | J69: =Analysis!K29 -> 2 | K69: =Analysis!L29 -> 5.0769231 | L69: =Analysis!M29 -> 7 | M69: =Analysis!N29 -> 1 | N69: =Analysis!O29 -> 2 | O69: =Analysis!C29 -> 1 | P69: =IF(I69<$I$74,"Below average engagement",IF(L69+M69>=3,"Engaged but needs follow-up","On track")) -> Below average engagement
B70: =Analysis!A30 -> Middle East & North Africa | F70: =Analysis!B30 -> 14 | G70: =Analysis!P30 -> 14 | H70: =Analysis!G30 -> 4 | I70: =Analysis!J30 -> 0.28571429 | J70: =Analysis!K30 -> 5 | K70: =Analysis!L30 -> 6.2307692 | L70: =Analysis!M30 -> 2 | M70: =Analysis!N30 -> 1 | N70: =Analysis!O30 -> 1 | O70: =Analysis!C30 -> 0 | P70: =IF(I70<$I$74,"Below average engagement",IF(L70+M70>=3,"Engaged but needs follow-up","On track")) -> Engaged but needs follow-up
B71: =Analysis!A31 -> Sub-Saharan Africa | F71: =Analysis!B31 -> 14 | G71: =Analysis!P31 -> 12 | H71: =Analysis!G31 -> 5 | I71: =Analysis!J31 -> 0.35714286 | J71: =Analysis!K31 -> 5 | K71: =Analysis!L31 -> 7.0909091 | L71: =Analysis!M31 -> 7 | M71: =Analysis!N31 -> 4 | N71: =Analysis!O31 -> 2 | O71: =Analysis!C31 -> 2 | P71: =IF(I71<$I$74,"Below average engagement",IF(L71+M71>=3,"Engaged but needs follow-up","On track")) -> Engaged but needs follow-up
B72: =Analysis!A32 -> Americas | F72: =Analysis!B32 -> 14 | G72: =Analysis!P32 -> 12 | H72: =Analysis!G32 -> 3 | I72: =Analysis!J32 -> 0.21428571 | J72: =Analysis!K32 -> 1 | K72: =Analysis!L32 -> 5.2727273 | L72: =Analysis!M32 -> 4 | M72: =Analysis!N32 -> 1 | N72: =Analysis!O32 -> 2 | O72: =Analysis!C32 -> 2 | P72: =IF(I72<$I$74,"Below average engagement",IF(L72+M72>=3,"Engaged but needs follow-up","On track")) -> Below average engagement
B73: =Analysis!A33 -> South & Central Asia | F73: =Analysis!B33 -> 8 | G73: =Analysis!P33 -> 7 | H73: =Analysis!G33 -> 1 | I73: =Analysis!J33 -> 0.125 | J73: =Analysis!K33 -> 1 | K73: =Analysis!L33 -> 5 | L73: =Analysis!M33 -> 4 | M73: =Analysis!N33 -> 2 | N73: =Analysis!O33 -> 0 | O73: =Analysis!C33 -> 1 | P73: =IF(I73<$I$74,"Below average engagement",IF(L73+M73>=3,"Engaged but needs follow-up","On track")) -> Below average engagement
B74: =Analysis!A34 -> Total | F74: =Analysis!B34 -> 84 | G74: =Analysis!P34 -> 74 | H74: =Analysis!G34 -> 19 | I74: =Analysis!J34 -> 0.22619048 | J74: =Analysis!K34 -> 17 | K74: =Analysis!L34 -> 5.8823529 | L74: =Analysis!M34 -> 30 | M74: =Analysis!N34 -> 13 | N74: =Analysis!O34 -> 8 | O74: =Analysis!C34 -> 10 | P74: Overall
B76: PRIORITY ATTENTION LIST - live embassies needing action first (ranked by Priority Score)
B77: # | C77: Embassy | E77: Region | H77: Status | J77: Owner | L77: Engage-ment | M77: Days since contact | N77: Next follow-up | O77: Issues
B78: 1 | C78: =IFERROR(INDEX(Clean_Data!$B$2:$B$500,MATCH($T78,Clean_Data!$A$2:$A$500,0))&"","") -> Ghana | E78: =IFERROR(INDEX(Clean_Data!$C$2:$C$500,MATCH($T78,Clean_Data!$A$2:$A$500,0))&"","") -> Sub-Saharan Africa | H78: =IFERROR(INDEX(Clean_Data!$H$2:$H$500,MATCH($T78,Clean_Data!$A$2:$A$500,0))&"","") -> Engaged | J78: =IFERROR(INDEX(Clean_Data!$I$2:$I$500,MATCH($T78,Clean_Data!$A$2:$A$500,0))&"","") -> Anita Deshmukh | L78: =IFERROR(INDEX(Clean_Data!$N$2:$N$500,MATCH($T78,Clean_Data!$A$2:$A$500,0))&"","") -> High | M78: =IFERROR(INDEX(Clean_Data!$R$2:$R$500,MATCH($T78,Clean_Data!$A$2:$A$500,0)),"") -> 330 | N78: =IFERROR(INDEX(Clean_Data!$L$2:$L$500,MATCH($T78,Clean_Data!$A$2:$A$500,0)),"") -> 46290 | O78: =IFERROR(INDEX(Clean_Data!$AB$2:$AB$500,MATCH($T78,Clean_Data!$A$2:$A$500,0))&"","") -> Follow-up overdue. No contact 90+ days. Date error (last < first). | T78: EMB-053
B79: 2 | C79: =IFERROR(INDEX(Clean_Data!$B$2:$B$500,MATCH($T79,Clean_Data!$A$2:$A$500,0))&"","") -> Ethiopia | E79: =IFERROR(INDEX(Clean_Data!$C$2:$C$500,MATCH($T79,Clean_Data!$A$2:$A$500,0))&"","") -> Sub-Saharan Africa | H79: =IFERROR(INDEX(Clean_Data!$H$2:$H$500,MATCH($T79,Clean_Data!$A$2:$A$500,0))&"","") -> Engaged | J79: =IFERROR(INDEX(Clean_Data!$I$2:$I$500,MATCH($T79,Clean_Data!$A$2:$A$500,0))&"","") -> Neha Kulkarni | L79: =IFERROR(INDEX(Clean_Data!$N$2:$N$500,MATCH($T79,Clean_Data!$A$2:$A$500,0))&"","") -> High | M79: =IFERROR(INDEX(Clean_Data!$R$2:$R$500,MATCH($T79,Clean_Data!$A$2:$A$500,0)),"") -> 227 | N79: =IFERROR(INDEX(Clean_Data!$L$2:$L$500,MATCH($T79,Clean_Data!$A$2:$A$500,0)),"") -> 46090 | O79: =IFERROR(INDEX(Clean_Data!$AB$2:$AB$500,MATCH($T79,Clean_Data!$A$2:$A$500,0))&"","") -> Follow-up overdue. No contact 90+ days. | T79: EMB-052
B80: 3 | C80: =IFERROR(INDEX(Clean_Data!$B$2:$B$500,MATCH($T80,Clean_Data!$A$2:$A$500,0))&"","") -> Russia | E80: =IFERROR(INDEX(Clean_Data!$C$2:$C$500,MATCH($T80,Clean_Data!$A$2:$A$500,0))&"","") -> Europe | H80: =IFERROR(INDEX(Clean_Data!$H$2:$H$500,MATCH($T80,Clean_Data!$A$2:$A$500,0))&"","") -> Engaged | J80: =IFERROR(INDEX(Clean_Data!$I$2:$I$500,MATCH($T80,Clean_Data!$A$2:$A$500,0))&"","") -> Neha Kulkarni | L80: =IFERROR(INDEX(Clean_Data!$N$2:$N$500,MATCH($T80,Clean_Data!$A$2:$A$500,0))&"","") -> High | M80: =IFERROR(INDEX(Clean_Data!$R$2:$R$500,MATCH($T80,Clean_Data!$A$2:$A$500,0)),"") -> 217 | N80: =IFERROR(INDEX(Clean_Data!$L$2:$L$500,MATCH($T80,Clean_Data!$A$2:$A$500,0)),"") -> 46122 | O80: =IFERROR(INDEX(Clean_Data!$AB$2:$AB$500,MATCH($T80,Clean_Data!$A$2:$A$500,0))&"","") -> Follow-up overdue. No contact 90+ days. | T80: EMB-020
B81: 4 | C81: =IFERROR(INDEX(Clean_Data!$B$2:$B$500,MATCH($T81,Clean_Data!$A$2:$A$500,0))&"","") -> Indonesia | E81: =IFERROR(INDEX(Clean_Data!$C$2:$C$500,MATCH($T81,Clean_Data!$A$2:$A$500,0))&"","") -> Asia-Pacific | H81: =IFERROR(INDEX(Clean_Data!$H$2:$H$500,MATCH($T81,Clean_Data!$A$2:$A$500,0))&"","") -> Initial Contact | J81: =IFERROR(INDEX(Clean_Data!$I$2:$I$500,MATCH($T81,Clean_Data!$A$2:$A$500,0))&"","") | L81: =IFERROR(INDEX(Clean_Data!$N$2:$N$500,MATCH($T81,Clean_Data!$A$2:$A$500,0))&"","") -> Medium | M81: =IFERROR(INDEX(Clean_Data!$R$2:$R$500,MATCH($T81,Clean_Data!$A$2:$A$500,0)),"") -> 127 | N81: =IFERROR(INDEX(Clean_Data!$L$2:$L$500,MATCH($T81,Clean_Data!$A$2:$A$500,0)),"") -> 46228 | O81: =IFERROR(INDEX(Clean_Data!$AB$2:$AB$500,MATCH($T81,Clean_Data!$A$2:$A$500,0))&"","") -> Follow-up overdue. No contact 90+ days. No owner. | T81: EMB-024
B82: 5 | C82: =IFERROR(INDEX(Clean_Data!$B$2:$B$500,MATCH($T82,Clean_Data!$A$2:$A$500,0))&"","") -> Ireland | E82: =IFERROR(INDEX(Clean_Data!$C$2:$C$500,MATCH($T82,Clean_Data!$A$2:$A$500,0))&"","") -> Europe | H82: =IFERROR(INDEX(Clean_Data!$H$2:$H$500,MATCH($T82,Clean_Data!$A$2:$A$500,0))&"","") -> In Discussion | J82: =IFERROR(INDEX(Clean_Data!$I$2:$I$500,MATCH($T82,Clean_Data!$A$2:$A$500,0))&"","") -> Sameer Khan | L82: =IFERROR(INDEX(Clean_Data!$N$2:$N$500,MATCH($T82,Clean_Data!$A$2:$A$500,0))&"","") -> Medium | M82: =IFERROR(INDEX(Clean_Data!$R$2:$R$500,MATCH($T82,Clean_Data!$A$2:$A$500,0)),"") -> 213 | N82: =IFERROR(INDEX(Clean_Data!$L$2:$L$500,MATCH($T82,Clean_Data!$A$2:$A$500,0)),"") -> 46128 | O82: =IFERROR(INDEX(Clean_Data!$AB$2:$AB$500,MATCH($T82,Clean_Data!$A$2:$A$500,0))&"","") -> Follow-up overdue. No contact 90+ days. | T82: EMB-018
B83: 6 | C83: =IFERROR(INDEX(Clean_Data!$B$2:$B$500,MATCH($T83,Clean_Data!$A$2:$A$500,0))&"","") -> Nigeria | E83: =IFERROR(INDEX(Clean_Data!$C$2:$C$500,MATCH($T83,Clean_Data!$A$2:$A$500,0))&"","") -> Sub-Saharan Africa | H83: =IFERROR(INDEX(Clean_Data!$H$2:$H$500,MATCH($T83,Clean_Data!$A$2:$A$500,0))&"","") -> Engaged | J83: =IFERROR(INDEX(Clean_Data!$I$2:$I$500,MATCH($T83,Clean_Data!$A$2:$A$500,0))&"","") -> Arjun Mehta | L83: =IFERROR(INDEX(Clean_Data!$N$2:$N$500,MATCH($T83,Clean_Data!$A$2:$A$500,0))&"","") -> Medium | M83: =IFERROR(INDEX(Clean_Data!$R$2:$R$500,MATCH($T83,Clean_Data!$A$2:$A$500,0)),"") -> 140 | N83: =IFERROR(INDEX(Clean_Data!$L$2:$L$500,MATCH($T83,Clean_Data!$A$2:$A$500,0)),"") -> 46203 | O83: =IFERROR(INDEX(Clean_Data!$AB$2:$AB$500,MATCH($T83,Clean_Data!$A$2:$A$500,0))&"","") -> Follow-up overdue. No contact 90+ days. Remarks conflict with status. | T83: EMB-050
B84: 7 | C84: =IFERROR(INDEX(Clean_Data!$B$2:$B$500,MATCH($T84,Clean_Data!$A$2:$A$500,0))&"","") -> Iraq | E84: =IFERROR(INDEX(Clean_Data!$C$2:$C$500,MATCH($T84,Clean_Data!$A$2:$A$500,0))&"","") -> Middle East & North Africa | H84: =IFERROR(INDEX(Clean_Data!$H$2:$H$500,MATCH($T84,Clean_Data!$A$2:$A$500,0))&"","") -> In Discussion | J84: =IFERROR(INDEX(Clean_Data!$I$2:$I$500,MATCH($T84,Clean_Data!$A$2:$A$500,0))&"","") -> Sameer Khan | L84: =IFERROR(INDEX(Clean_Data!$N$2:$N$500,MATCH($T84,Clean_Data!$A$2:$A$500,0))&"","") -> Medium | M84: =IFERROR(INDEX(Clean_Data!$R$2:$R$500,MATCH($T84,Clean_Data!$A$2:$A$500,0)),"") -> 131 | N84: =IFERROR(INDEX(Clean_Data!$L$2:$L$500,MATCH($T84,Clean_Data!$A$2:$A$500,0)),"") -> 46210 | O84: =IFERROR(INDEX(Clean_Data!$AB$2:$AB$500,MATCH($T84,Clean_Data!$A$2:$A$500,0))&"","") -> Follow-up overdue. No contact 90+ days. | T84: EMB-042
B85: 8 | C85: =IFERROR(INDEX(Clean_Data!$B$2:$B$500,MATCH($T85,Clean_Data!$A$2:$A$500,0))&"","") -> Maldives | E85: =IFERROR(INDEX(Clean_Data!$C$2:$C$500,MATCH($T85,Clean_Data!$A$2:$A$500,0))&"","") -> South & Central Asia | H85: =IFERROR(INDEX(Clean_Data!$H$2:$H$500,MATCH($T85,Clean_Data!$A$2:$A$500,0))&"","") -> In Discussion | J85: =IFERROR(INDEX(Clean_Data!$I$2:$I$500,MATCH($T85,Clean_Data!$A$2:$A$500,0))&"","") -> Arjun Mehta | L85: =IFERROR(INDEX(Clean_Data!$N$2:$N$500,MATCH($T85,Clean_Data!$A$2:$A$500,0))&"","") -> Medium | M85: =IFERROR(INDEX(Clean_Data!$R$2:$R$500,MATCH($T85,Clean_Data!$A$2:$A$500,0)),"") -> 107 | N85: =IFERROR(INDEX(Clean_Data!$L$2:$L$500,MATCH($T85,Clean_Data!$A$2:$A$500,0)),"") -> 46242 | O85: =IFERROR(INDEX(Clean_Data!$AB$2:$AB$500,MATCH($T85,Clean_Data!$A$2:$A$500,0))&"","") -> Follow-up overdue. No contact 90+ days. | T85: EMB-081
B86: 9 | C86: =IFERROR(INDEX(Clean_Data!$B$2:$B$500,MATCH($T86,Clean_Data!$A$2:$A$500,0))&"","") -> Denmark | E86: =IFERROR(INDEX(Clean_Data!$C$2:$C$500,MATCH($T86,Clean_Data!$A$2:$A$500,0))&"","") -> Europe | H86: =IFERROR(INDEX(Clean_Data!$H$2:$H$500,MATCH($T86,Clean_Data!$A$2:$A$500,0))&"","") -> Meeting Scheduled | J86: =IFERROR(INDEX(Clean_Data!$I$2:$I$500,MATCH($T86,Clean_Data!$A$2:$A$500,0))&"","") -> Sameer Khan | L86: =IFERROR(INDEX(Clean_Data!$N$2:$N$500,MATCH($T86,Clean_Data!$A$2:$A$500,0))&"","") -> Medium | M86: =IFERROR(INDEX(Clean_Data!$R$2:$R$500,MATCH($T86,Clean_Data!$A$2:$A$500,0)),"") -> 105 | N86: =IFERROR(INDEX(Clean_Data!$L$2:$L$500,MATCH($T86,Clean_Data!$A$2:$A$500,0)),"") -> 46215 | O86: =IFERROR(INDEX(Clean_Data!$AB$2:$AB$500,MATCH($T86,Clean_Data!$A$2:$A$500,0))&"","") -> Follow-up overdue. No contact 90+ days. | T86: EMB-012
B87: 10 | C87: =IFERROR(INDEX(Clean_Data!$B$2:$B$500,MATCH($T87,Clean_Data!$A$2:$A$500,0))&"","") -> Peru | E87: =IFERROR(INDEX(Clean_Data!$C$2:$C$500,MATCH($T87,Clean_Data!$A$2:$A$500,0))&"","") -> Americas | H87: =IFERROR(INDEX(Clean_Data!$H$2:$H$500,MATCH($T87,Clean_Data!$A$2:$A$500,0))&"","") -> Initial Contact | J87: =IFERROR(INDEX(Clean_Data!$I$2:$I$500,MATCH($T87,Clean_Data!$A$2:$A$500,0))&"","") -> Priya Nair | L87: =IFERROR(INDEX(Clean_Data!$N$2:$N$500,MATCH($T87,Clean_Data!$A$2:$A$500,0))&"","") -> Low | M87: =IFERROR(INDEX(Clean_Data!$R$2:$R$500,MATCH($T87,Clean_Data!$A$2:$A$500,0)),"") -> 224 | N87: =IFERROR(INDEX(Clean_Data!$L$2:$L$500,MATCH($T87,Clean_Data!$A$2:$A$500,0)),"") -> 46134 | O87: =IFERROR(INDEX(Clean_Data!$AB$2:$AB$500,MATCH($T87,Clean_Data!$A$2:$A$500,0))&"","") -> Follow-up overdue. No contact 90+ days. | T87: EMB-070
B88: 11 | C88: =IFERROR(INDEX(Clean_Data!$B$2:$B$500,MATCH($T88,Clean_Data!$A$2:$A$500,0))&"","") -> Germany | E88: =IFERROR(INDEX(Clean_Data!$C$2:$C$500,MATCH($T88,Clean_Data!$A$2:$A$500,0))&"","") -> Europe | H88: =IFERROR(INDEX(Clean_Data!$H$2:$H$500,MATCH($T88,Clean_Data!$A$2:$A$500,0))&"","") -> Initial Contact | J88: =IFERROR(INDEX(Clean_Data!$I$2:$I$500,MATCH($T88,Clean_Data!$A$2:$A$500,0))&"","") -> Priya Nair | L88: =IFERROR(INDEX(Clean_Data!$N$2:$N$500,MATCH($T88,Clean_Data!$A$2:$A$500,0))&"","") -> Low | M88: =IFERROR(INDEX(Clean_Data!$R$2:$R$500,MATCH($T88,Clean_Data!$A$2:$A$500,0)),"") -> 222 | N88: =IFERROR(INDEX(Clean_Data!$L$2:$L$500,MATCH($T88,Clean_Data!$A$2:$A$500,0)),"") -> 46132 | O88: =IFERROR(INDEX(Clean_Data!$AB$2:$AB$500,MATCH($T88,Clean_Data!$A$2:$A$500,0))&"","") -> Follow-up overdue. No contact 90+ days. | T88: EMB-002
B89: 12 | C89: =IFERROR(INDEX(Clean_Data!$B$2:$B$500,MATCH($T89,Clean_Data!$A$2:$A$500,0))&"","") -> Zimbabwe | E89: =IFERROR(INDEX(Clean_Data!$C$2:$C$500,MATCH($T89,Clean_Data!$A$2:$A$500,0))&"","") -> Sub-Saharan Africa | H89: =IFERROR(INDEX(Clean_Data!$H$2:$H$500,MATCH($T89,Clean_Data!$A$2:$A$500,0))&"","") -> Initial Contact | J89: =IFERROR(INDEX(Clean_Data!$I$2:$I$500,MATCH($T89,Clean_Data!$A$2:$A$500,0))&"","") -> Arjun Mehta | L89: =IFERROR(INDEX(Clean_Data!$N$2:$N$500,MATCH($T89,Clean_Data!$A$2:$A$500,0))&"","") -> Low | M89: =IFERROR(INDEX(Clean_Data!$R$2:$R$500,MATCH($T89,Clean_Data!$A$2:$A$500,0)),"") -> 221 | N89: =IFERROR(INDEX(Clean_Data!$L$2:$L$500,MATCH($T89,Clean_Data!$A$2:$A$500,0)),"") -> 46120 | O89: =IFERROR(INDEX(Clean_Data!$AB$2:$AB$500,MATCH($T89,Clean_Data!$A$2:$A$500,0))&"","") -> Follow-up overdue. No contact 90+ days. | T89: EMB-057
B90: Priority Score = overdue follow-up (2) + stale (2) + no follow-up date (1) + no owner (1) + engagement High (2) / Medium (1). Higher engagement ranks higher because relationships at risk are the most valuable to protect. Full ranking: Clean_Data column AA.
B91: Note: figures are calculated by formula from Clean_Data and update when data is refreshed. The attention-list ranking (IDs) is a snapshot at the report date; re-sort Clean_Data by Priority Score to refresh it.

Sheet Data Quality Review
A1: Data Quality Review - Embassy Outreach Database
A2: ="Source: "&COUNTA(Raw_Data!A2:A92)+COUNTBLANK(Raw_Data!A2:A92)&" raw records reviewed | "&COUNTA(Clean_Data!A2:A500)&" unique embassies after cleaning | Report date "&TEXT(Analysis!B3,"dd-mmm-yyyy") -> Source: 91 raw records reviewed | 84 unique embassies after cleaning | Report date 05-Oct-2026
A4: Raw records | C4: Records with >=1 issue | E4: Clean-record rate | G4: Duplicates removed
A5: =ROWS(Raw_Data!A2:A92) -> 91 | C5: =DQ_Checks!$V$93 -> 72 | E5: =1-C5/A5 -> 0.20879121 | G5: =ROWS(Raw_Data!A2:A92)-COUNTA(Clean_Data!A2:A500) -> 7
A7: A. Issue log (counts are live formulas on Raw_Data / Clean_Data)
A8: # | B8: Category | C8: Issue | D8: Field(s) | E8: Records affected | F8: % of base | G8: Severity | H8: Why it matters | I8: Recommended action
A9: 1 | B9: Uniqueness | C9: Duplicate embassy records (same ID or same embassy under a different name/ID) | D9: Embassy_ID, Country | E9: =ROWS(Raw_Data!A2:A92)-COUNTA(Clean_Data!A2:A500) -> 7 | F9: =IF((ROWS(Raw_Data!A2:A92))=0,0,E9/(ROWS(Raw_Data!A2:A92))) -> 0.076923077 | G9: High | H9: Double-counts embassies and splits interaction history, inflating pipeline totals. | I9: Enforce one record per embassy; use a unique-ID lookup and a duplicate check before saving new entries.
A10: 2 | B10: Uniqueness | C10: Rows sharing an Embassy_ID with another row | D10: Embassy_ID | E10: =DQ_Checks!$Q$93 -> 8 | F10: =IF((ROWS(Raw_Data!A2:A92))=0,0,E10/(ROWS(Raw_Data!A2:A92))) -> 0.087912088 | G10: High | H10: Same ID used for stale and updated versions - cannot tell which is current. | I10: Keep the latest record; archive history in a separate interaction log.
A11: 3 | B11: Completeness | C11: Embassy_ID missing | D11: Embassy_ID | E11: =DQ_Checks!$T$93 -> 2 | F11: =IF((ROWS(Raw_Data!A2:A92))=0,0,E11/(ROWS(Raw_Data!A2:A92))) -> 0.021978022 | G11: High | H11: Record cannot be linked or de-duplicated reliably. | I11: Assign IDs from the master embassy list (done in Clean_Data).
A12: 4 | B12: Consistency | C12: Country name not matching master list (aliases, case, stray spaces) | D12: Country | E12: =DQ_Checks!$C$93 -> 11 | F12: =IF((ROWS(Raw_Data!A2:A92))=0,0,E12/(ROWS(Raw_Data!A2:A92))) -> 0.12087912 | G12: High | H12: Region/country roll-ups and lookups fail (e.g. 'USA' vs 'United States'). | I12: Use a dropdown tied to the master country list.
A13: 5 | B13: Consistency | C13: Outreach status entered in non-standard spellings | D13: Outreach_Status | E13: =DQ_Checks!$F$93 -> 14 | F13: =IF((ROWS(Raw_Data!A2:A92))=0,0,E13/(ROWS(Raw_Data!A2:A92))) -> 0.15384615 | G13: High | H13: Status counts split across variants; pipeline funnel is unreliable until cleaned. | I13: Restrict to 7 standard statuses via data validation.
A14: 6 | B14: Completeness | C14: Region missing | D14: Region | E14: =DQ_Checks!$D$93 -> 5 | F14: =IF((ROWS(Raw_Data!A2:A92))=0,0,E14/(ROWS(Raw_Data!A2:A92))) -> 0.054945055 | G14: Medium | H14: Embassy is excluded from regional analysis. | I14: Derive region from country (done in Clean_Data).
A15: 7 | B15: Consistency | C15: Region written in non-standard form (APAC, MENA, Africa...) | D15: Region | E15: =DQ_Checks!$E$93 -> 8 | F15: =IF((ROWS(Raw_Data!A2:A92))=0,0,E15/(ROWS(Raw_Data!A2:A92))) -> 0.087912088 | G15: Medium | H15: Regional totals fragment. | I15: Standard 6-region list with dropdown.
A16: 8 | B16: Accuracy | C16: Region conflicts with the country's standard region (e.g. Egypt tagged Sub-Saharan Africa) | D16: Region, Country | E16: =DQ_Checks!$U$93 -> 3 | F16: =IF((ROWS(Raw_Data!A2:A92))=0,0,E16/(ROWS(Raw_Data!A2:A92))) -> 0.032967033 | G16: Medium | H16: Mis-allocates embassies between regions. | I16: Region derived from master list, not typed manually.
A17: 9 | B17: Completeness | C17: Email missing | D17: Email | E17: =DQ_Checks!$G$93 -> 7 | F17: =IF((ROWS(Raw_Data!A2:A92))=0,0,E17/(ROWS(Raw_Data!A2:A92))) -> 0.076923077 | G17: Medium | H17: Embassy cannot be contacted by email. | I17: Source from embassy directory / protocol office.
A18: 10 | B18: Validity | C18: Email invalid (no '@' or no domain dot) | D18: Email | E18: =DQ_Checks!$H$93 -> 7 | F18: =IF((ROWS(Raw_Data!A2:A92))=0,0,E18/(ROWS(Raw_Data!A2:A92))) -> 0.076923077 | G18: Medium | H18: Bounced outreach and false 'contactable' impression. | I18: Validate on entry; verify bounced addresses.
A19: 11 | B19: Completeness | C19: Phone missing | D19: Phone | E19: =DQ_Checks!$I$93 -> 8 | F19: =IF((ROWS(Raw_Data!A2:A92))=0,0,E19/(ROWS(Raw_Data!A2:A92))) -> 0.087912088 | G19: Low | H19: No fallback contact route. | I19: Collect landline/mobile for each primary contact.
A20: 12 | B20: Consistency | C20: Phone in mixed or incomplete formats | D20: Phone | E20: =DQ_Checks!$J$93 -> 12 | F20: =IF((ROWS(Raw_Data!A2:A92))=0,0,E20/(ROWS(Raw_Data!A2:A92))) -> 0.13186813 | G20: Low | H20: Hard to dial or de-duplicate; truncated numbers unusable. | I20: Standard format +91 XX XXXX XXXX; re-verify truncated numbers.
A21: 13 | B21: Completeness | C21: Outreach owner not assigned (raw) | D21: Outreach_Owner | E21: =DQ_Checks!$K$93 -> 9 | F21: =IF((ROWS(Raw_Data!A2:A92))=0,0,E21/(ROWS(Raw_Data!A2:A92))) -> 0.098901099 | G21: High | H21: No accountability for follow-up. | I21: Assign an owner to every embassy; review monthly.
A22: 14 | B22: Completeness | C22: Engagement level missing for contacted embassies | D22: Engagement_Level | E22: =DQ_Checks!$L$93 -> 11 | F22: =IF((ROWS(Raw_Data!A2:A92))=0,0,E22/(ROWS(Raw_Data!A2:A92))) -> 0.12087912 | G22: Medium | H22: Cannot prioritise by engagement strength. | I22: Make engagement rating mandatory once status > Not Started.
A23: 15 | B23: Completeness | C23: Last contact date missing for contacted embassies | D23: Last_Contact_Date | E23: =DQ_Checks!$S$93 -> 6 | F23: =IF((ROWS(Raw_Data!A2:A92))=0,0,E23/(ROWS(Raw_Data!A2:A92))) -> 0.065934066 | G23: High | H23: Recency / staleness cannot be measured. | I23: Mandatory date field when status changes.
A24: 16 | B24: Completeness | C24: Interactions count blank | D24: Interactions | E24: =DQ_Checks!$N$93 -> 6 | F24: =IF((ROWS(Raw_Data!A2:A92))=0,0,E24/(ROWS(Raw_Data!A2:A92))) -> 0.065934066 | G24: Low | H24: Understates engagement effort. | I24: Default to 0; update from the interaction log.
A25: 17 | B25: Validity | C25: Negative number of interactions | D25: Interactions | E25: =DQ_Checks!$O$93 -> 1 | F25: =IF((ROWS(Raw_Data!A2:A92))=0,0,E25/(ROWS(Raw_Data!A2:A92))) -> 0.010989011 | G25: Medium | H25: Impossible value distorts averages. | I25: Add >=0 validation rule.
A26: 18 | B26: Validity | C26: Dates stored as text in mixed formats (dd/mm/yyyy, yyyy-mm-dd, dd-mmm-yy) | D26: First/Last/Next dates | E26: =DQ_Checks!$M$93 -> 8 | F26: =IF((ROWS(Raw_Data!A2:A92))=0,0,E26/(ROWS(Raw_Data!A2:A92))) -> 0.087912088 | G26: Medium | H26: Text dates fail date maths; dd/mm vs mm/dd ambiguity risk. | I26: Store true Excel dates; use a date-picker.
A27: 19 | B27: Consistency | C27: Extra leading/trailing spaces in names | D27: Country, Contact_Person | E27: =DQ_Checks!$P$93 -> 9 | F27: =IF((ROWS(Raw_Data!A2:A92))=0,0,E27/(ROWS(Raw_Data!A2:A92))) -> 0.098901099 | G27: Low | H27: Breaks look-ups and filters. | I27: TRIM on entry/import.
A28: 20 | B28: Accuracy | C28: 'Not Started' embassies that show interactions or a last-contact date | D28: Status, Interactions, Last contact | E28: =DQ_Checks!$R$93 -> 3 | F28: =IF((ROWS(Raw_Data!A2:A92))=0,0,E28/(ROWS(Raw_Data!A2:A92))) -> 0.032967033 | G28: Medium | H28: Status is understated or activity is mis-recorded. | I28: Confirm with owner and correct status.
A29: 21 | B29: Accuracy | C29: Last contact earlier than First contact (cleaned data) | D29: First/Last contact | E29: =SUM(Clean_Data!X2:X500) -> 4 | F29: =IF((COUNTA(Clean_Data!$A$2:$A$500))=0,0,E29/(COUNTA(Clean_Data!$A$2:$A$500))) -> 0.047619048 | G29: Medium | H29: Impossible chronology; recency metrics unreliable. | I29: Verify against correspondence; fix dates.
A30: 22 | B30: Accuracy | C30: Last contact date in the future (cleaned data) | D30: Last contact | E30: =SUM(Clean_Data!Y2:Y500) -> 3 | F30: =IF((COUNTA(Clean_Data!$A$2:$A$500))=0,0,E30/(COUNTA(Clean_Data!$A$2:$A$500))) -> 0.035714286 | G30: High | H30: Cannot be true as of the report date; hides stale accounts. | I30: Correct to actual contact date.
A31: 23 | B31: Accuracy | C31: Remarks say 'declined' while status is live (cleaned data) | D31: Remarks vs Status | E31: =SUM(Clean_Data!Z2:Z500) -> 3 | F31: =IF((COUNTA(Clean_Data!$A$2:$A$500))=0,0,E31/(COUNTA(Clean_Data!$A$2:$A$500))) -> 0.035714286 | G31: High | H31: Pipeline overstated; resources spent on declined embassies. | I31: Reconcile status with remarks; move to Closed if confirmed.
A32: 24 | B32: Timeliness | C32: Live embassies with no follow-up date (cleaned data) | D32: Next_Followup_Date | E32: =SUM(Clean_Data!U2:U500) -> 7 | F32: =IF((COUNTA(Clean_Data!$A$2:$A$500))=0,0,E32/(COUNTA(Clean_Data!$A$2:$A$500))) -> 0.083333333 | G32: High | H32: No scheduled next step - risk of silent drop-off. | I32: Require a next-step date for every live embassy.
A33: 25 | B33: Timeliness | C33: Follow-up date already passed (overdue) | D33: Next_Followup_Date | E33: =SUM(Clean_Data!S2:S500) -> 30 | F33: =IF((COUNTA(Clean_Data!$A$2:$A$500))=0,0,E33/(COUNTA(Clean_Data!$A$2:$A$500))) -> 0.35714286 | G33: High | H33: Missed commitments damage relationships. | I33: Owners to action or reschedule within 1 week.
A34: 26 | B34: Timeliness | C34: Live embassies with no contact beyond the stale threshold | D34: Last_Contact_Date | E34: =SUM(Clean_Data!T2:T500) -> 13 | F34: =IF((COUNTA(Clean_Data!$A$2:$A$500))=0,0,E34/(COUNTA(Clean_Data!$A$2:$A$500))) -> 0.1547619 | G34: High | H34: Relationships going cold. | I34: Re-engage or formally pause.
A35: 27 | B35: Completeness | C35: Outreach owner still missing after cleaning | D35: Outreach_Owner | E35: =COUNTIFS(Clean_Data!A2:A500,"<>",Clean_Data!I2:I500,"") -> 8 | F35: =IF((COUNTA(Clean_Data!$A$2:$A$500))=0,0,E35/(COUNTA(Clean_Data!$A$2:$A$500))) -> 0.095238095 | G35: High | H35: Needs a manual decision - cannot be derived. | I35: Management to assign owners.
A36: 28 | B36: Validity | C36: Email still invalid/missing after cleaning | D36: Email | E36: =COUNTIF(Clean_Data!V2:V500,"Invalid")+COUNTIF(Clean_Data!V2:V500,"Missing") -> 13 | F36: =IF((COUNTA(Clean_Data!$A$2:$A$500))=0,0,E36/(COUNTA(Clean_Data!$A$2:$A$500))) -> 0.1547619 | G36: Medium | H36: Needs source verification. | I36: Verify with embassy.
A37: % of base: issues #1-20 use the raw record count; issues #21 onward use the cleaned unique-embassy count. Severity is a judgement based on impact on decision-making.
A39: B. Key observations
A40: ="1. Only "&TEXT(E5,"0%")&" of raw records are fully clean; "&C5&" of "&A5&" records carry at least one issue, so the raw file should not be used for reporting without cleaning." -> 1. Only 21% of raw records are fully clean; 72 of 91 records carry at least one issue, so the raw file should not be used for reporting without cleaning.
A41: ="2. "&G5&" duplicate records were removed - the raw file would have overstated the number of embassies by "&TEXT(G5/COUNTA(Clean_Data!A2:A500),"0.0%")&"." -> 2. 7 duplicate records were removed - the raw file would have overstated the number of embassies by 8.3%.
A42: ="3. Status, region and country are free-text, which produced "&DQ_Checks!$F$93&" non-standard statuses, "&DQ_Checks!$C$93&" country-name variants and "&DQ_Checks!$E$93&" non-standard regions." -> 3. Status, region and country are free-text, which produced 14 non-standard statuses, 11 country-name variants and 8 non-standard regions.
A43: ="4. Process gaps matter more than typing errors: "&SUM(Clean_Data!S2:S500)&" live embassies have overdue follow-ups, "&SUM(Clean_Data!U2:U500)&" have no next-step date and "&SUM(Clean_Data!T2:T500)&" have gone silent for "&Analysis!B4&"+ days." -> 4. Process gaps matter more than typing errors: 30 live embassies have overdue follow-ups, 7 have no next-step date and 13 have gone silent for 90+ days.
...

Sheet Analysis
A1: Analysis Workings - all dashboard figures are calculated here from Clean_Data
A3: Report date (input) | B3: 46300 | C3: Fixed as-of date so the report is reproducible. Replace with =TODAY() for a live view.
A4: Stale threshold - days without contact (input) | B4: 90 | C4: Assumption: a live embassy with no recorded contact in this many days is 'stale'.
A5: Attention list size | B5: 12 | C5: Top records by Priority Score shown on the Dashboard.
A7: 1. Outreach status pipeline
A8: Outreach Status | B8: Embassies | C8: % of Total
A9: Not Started | B9: =COUNTIF(Clean_Data!$H$2:$H$500,A9) -> 10 | C9: =IF($B$16=0,0,B9/$B$16) -> 0.11904762
A10: Initial Contact | B10: =COUNTIF(Clean_Data!$H$2:$H$500,A10) -> 15 | C10: =IF($B$16=0,0,B10/$B$16) -> 0.17857143
A11: In Discussion | B11: =COUNTIF(Clean_Data!$H$2:$H$500,A11) -> 14 | C11: =IF($B$16=0,0,B11/$B$16) -> 0.16666667
A12: Meeting Scheduled | B12: =COUNTIF(Clean_Data!$H$2:$H$500,A12) -> 11 | C12: =IF($B$16=0,0,B12/$B$16) -> 0.13095238
A13: Engaged | B13: =COUNTIF(Clean_Data!$H$2:$H$500,A13) -> 19 | C13: =IF($B$16=0,0,B13/$B$16) -> 0.22619048
A14: On Hold | B14: =COUNTIF(Clean_Data!$H$2:$H$500,A14) -> 11 | C14: =IF($B$16=0,0,B14/$B$16) -> 0.13095238
A15: Closed | B15: =COUNTIF(Clean_Data!$H$2:$H$500,A15) -> 4 | C15: =IF($B$16=0,0,B15/$B$16) -> 0.047619048
A16: Total | B16: =SUM(B9:B15) -> 84 | C16: =SUM(C9:C15) -> 1
A18: 2. Engagement level
A19: Engagement Level | B19: Embassies | C19: % of Total
A20: High | B20: =COUNTIF(Clean_Data!$N$2:$N$500,A20) -> 17 | C20: =IF($B$24=0,0,B20/$B$24) -> 0.20238095
A21: Medium | B21: =COUNTIF(Clean_Data!$N$2:$N$500,A21) -> 22 | C21: =IF($B$24=0,0,B21/$B$24) -> 0.26190476
A22: Low | B22: =COUNTIF(Clean_Data!$N$2:$N$500,A22) -> 25 | C22: =IF($B$24=0,0,B22/$B$24) -> 0.29761905
A23: Not rated | B23: =COUNTIFS(Clean_Data!$A$2:$A$500,"<>",Clean_Data!$N$2:$N$500,"") -> 20 | C23: =IF($B$24=0,0,B23/$B$24) -> 0.23809524
A24: Total | B24: =SUM(B20:B23) -> 84 | C24: =IF($B$24=0,0,B24/$B$24) -> 1
A26: 3. Regional performance
A27: Region | B27: Embassies | C27: Not Started | D27: Initial Contact | E27: In Discussion | F27: Meeting Scheduled | G27: Engaged | H27: On Hold | I27: Closed | J27: Engaged % | K27: High Engagement | L27: Avg Interactions | M27: Overdue Follow-ups | N27: Stale | O27: No Owner | P27: Contacted | Q27: Early / Active Stage | R27: On Hold / Closed
A28: Europe | B28: =COUNTIF(Clean_Data!$C$2:$C$500,$A28) -> 20 | C28: =COUNTIFS(Clean_Data!$C$2:$C$500,$A28,Clean_Data!$H$2:$H$500,"Not Started") -> 4 | D28: =COUNTIFS(Clean_Data!$C$2:$C$500,$A28,Clean_Data!$H$2:$H$500,"Initial Contact") -> 3 | E28: =COUNTIFS(Clean_Data!$C$2:$C$500,$A28,Clean_Data!$H$2:$H$500,"In Discussion") -> 4 | F28: =COUNTIFS(Clean_Data!$C$2:$C$500,$A28,Clean_Data!$H$2:$H$500,"Meeting Scheduled") -> 3 | G28: =COUNTIFS(Clean_Data!$C$2:$C$500,$A28,Clean_Data!$H$2:$H$500,"Engaged") -> 3 | H28: =COUNTIFS(Clean_Data!$C$2:$C$500,$A28,Clean_Data!$H$2:$H$500,"On Hold") -> 3 | I28: =COUNTIFS(Clean_Data!$C$2:$C$500,$A28,Clean_Data!$H$2:$H$500,"Closed") -> 0 | J28: =IF(B28=0,0,G28/B28) -> 0.15 | K28: =COUNTIFS(Clean_Data!$C$2:$C$500,$A28,Clean_Data!$N$2:$N$500,"High") -> 3 | L28: =IFERROR(AVERAGEIFS(Clean_Data!$M$2:$M$500,Clean_Data!$C$2:$C$500,$A28,Clean_Data!$H$2:$H$500,"<>Not Started"),0) -> 6.2142857 | M28: =SUMIFS(Clean_Data!$S$2:$S$500,Clean_Data!$C$2:$C$500,$A28) -> 6 | N28: =SUMIFS(Clean_Data!$T$2:$T$500,Clean_Data!$C$2:$C$500,$A28) -> 4 | O28: =COUNTIFS(Clean_Data!$C$2:$C$500,$A28,Clean_Data!$I$2:$I$500,"") -> 1 | P28: =B28-C28 -> 16 | Q28: =D28+E28+F28 -> 10 | R28: =H28+I28 -> 3
A29: Asia-Pacific | B29: =COUNTIF(Clean_Data!$C$2:$C$500,$A29) -> 14 | C29: =COUNTIFS(Clean_Data!$C$2:$C$500,$A29,Clean_Data!$H$2:$H$500,"Not Started") -> 1 | D29: =COUNTIFS(Clean_Data!$C$2:$C$500,$A29,Clean_Data!$H$2:$H$500,"Initial Contact") -> 2 | E29: =COUNTIFS(Clean_Data!$C$2:$C$500,$A29,Clean_Data!$H$2:$H$500,"In Discussion") -> 4 | F29: =COUNTIFS(Clean_Data!$C$2:$C$500,$A29,Clean_Data!$H$2:$H$500,"Meeting Scheduled") -> 2 | G29: =COUNTIFS(Clean_Data!$C$2:$C$500,$A29,Clean_Data!$H$2:$H$500,"Engaged") -> 3 | H29: =COUNTIFS(Clean_Data!$C$2:$C$500,$A29,Clean_Data!$H$2:$H$500,"On Hold") -> 1 | I29: =COUNTIFS(Clean_Data!$C$2:$C$500,$A29,Clean_Data!$H$2:$H$500,"Closed") -> 1 | J29: =IF(B29=0,0,G29/B29) -> 0.21428571 | K29: =COUNTIFS(Clean_Data!$C$2:$C$500,$A29,Clean_Data!$N$2:$N$500,"High") -> 2 | L29: =IFERROR(AVERAGEIFS(Clean_Data!$M$2:$M$500,Clean_Data!$C$2:$C$500,$A29,Clean_Data!$H$2:$H$500,"<>Not Started"),0) -> 5.0769231 | M29: =SUMIFS(Clean_Data!$S$2:$S$500,Clean_Data!$C$2:$C$500,$A29) -> 7 | N29: =SUMIFS(Clean_Data!$T$2:$T$500,Clean_Data!$C$2:$C$500,$A29) -> 1 | O29: =COUNTIFS(Clean_Data!$C$2:$C$500,$A29,Clean_Data!$I$2:$I$500,"") -> 2 | P29: =B29-C29 -> 13 | Q29: =D29+E29+F29 -> 8 | R29: =H29+I29 -> 2
A30: Middle East & North Africa | B30: =COUNTIF(Clean_Data!$C$2:$C$500,$A30) -> 14 | C30: =COUNTIFS(Clean_Data!$C$2:$C$500,$A30,Clean_Data!$H$2:$H$500,"Not Started") -> 0 | D30: =COUNTIFS(Clean_Data!$C$2:$C$500,$A30,Clean_Data!$H$2:$H$500,"Initial Contact") -> 2 | E30: =COUNTIFS(Clean_Data!$C$2:$C$500,$A30,Clean_Data!$H$2:$H$500,"In Discussion") -> 2 | F30: =COUNTIFS(Clean_Data!$C$2:$C$500,$A30,Clean_Data!$H$2:$H$500,"Meeting Scheduled") -> 1 | G30: =COUNTIFS(Clean_Data!$C$2:$C$500,$A30,Clean_Data!$H$2:$H$500,"Engaged") -> 4 | H30: =COUNTIFS(Clean_Data!$C$2:$C$500,$A30,Clean_Data!$H$2:$H$500,"On Hold") -> 3 | I30: =COUNTIFS(Clean_Data!$C$2:$C$500,$A30,Clean_Data!$H$2:$H$500,"Closed") -> 2 | J30: =IF(B30=0,0,G30/B30) -> 0.28571429 | K30: =COUNTIFS(Clean_Data!$C$2:$C$500,$A30,Clean_Data!$N$2:$N$500,"High") -> 5 | L30: =IFERROR(AVERAGEIFS(Clean_Data!$M$2:$M$500,Clean_Data!$C$2:$C$500,$A30,Clean_Data!$H$2:$H$500,"<>Not Started"),0) -> 6.2307692 | M30: =SUMIFS(Clean_Data!$S$2:$S$500,Clean_Data!$C$2:$C$500,$A30) -> 2 | N30: =SUMIFS(Clean_Data!$T$2:$T$500,Clean_Data!$C$2:$C$500,$A30) -> 1 | O30: =COUNTIFS(Clean_Data!$C$2:$C$500,$A30,Clean_Data!$I$2:$I$500,"") -> 1 | P30: =B30-C30 -> 14 | Q30: =D30+E30+F30 -> 5 | R30: =H30+I30 -> 5
A31: Sub-Saharan Africa | B31: =COUNTIF(Clean_Data!$C$2:$C$500,$A31) -> 14 | C31: =COUNTIFS(Clean_Data!$C$2:$C$500,$A31,Clean_Data!$H$2:$H$500,"Not Started") -> 2 | D31: =COUNTIFS(Clean_Data!$C$2:$C$500,$A31,Clean_Data!$H$2:$H$500,"Initial Contact") -> 1 | E31: =COUNTIFS(Clean_Data!$C$2:$C$500,$A31,Clean_Data!$H$2:$H$500,"In Discussion") -> 2 | F31: =COUNTIFS(Clean_Data!$C$2:$C$500,$A31,Clean_Data!$H$2:$H$500,"Meeting Scheduled") -> 1 | G31: =COUNTIFS(Clean_Data!$C$2:$C$500,$A31,Clean_Data!$H$2:$H$500,"Engaged") -> 5 | H31: =COUNTIFS(Clean_Data!$C$2:$C$500,$A31,Clean_Data!$H$2:$H$500,"On Hold") -> 3 | I31: =COUNTIFS(Clean_Data!$C$2:$C$500,$A31,Clean_Data!$H$2:$H$500,"Closed") -> 0 | J31: =IF(B31=0,0,G31/B31) -> 0.35714286 | K31: =COUNTIFS(Clean_Data!$C$2:$C$500,$A31,Clean_Data!$N$2:$N$500,"High") -> 5 | L31: =IFERROR(AVERAGEIFS(Clean_Data!$M$2:$M$500,Clean_Data!$C$2:$C$500,$A31,Clean_Data!$H$2:$H$500,"<>Not Started"),0) -> 7.0909091 | M31: =SUMIFS(Clean_Data!$S$2:$S$500,Clean_Data!$C$2:$C$500,$A31) -> 7 | N31: =SUMIFS(Clean_Data!$T$2:$T$500,Clean_Data!$C$2:$C$500,$A31) -> 4 | O31: =COUNTIFS(Clean_Data!$C$2:$C$500,$A31,Clean_Data!$I$2:$I$500,"") -> 2 | P31: =B31-C31 -> 12 | Q31: =D31+E31+F31 -> 4 | R31: =H31+I31 -> 3
A32: Americas | B32: =COUNTIF(Clean_Data!$C$2:$C$500,$A32) -> 14 | C32: =COUNTIFS(Clean_Data!$C$2:$C$500,$A32,Clean_Data!$H$2:$H$500,"Not Started") -> 2 | D32: =COUNTIFS(Clean_Data!$C$2:$C$500,$A32,Clean_Data!$H$2:$H$500,"Initial Contact") -> 4 | E32: =COUNTIFS(Clean_Data!$C$2:$C$500,$A32,Clean_Data!$H$2:$H$500,"In Discussion") -> 1 | F32: =COUNTIFS(Clean_Data!$C$2:$C$500,$A32,Clean_Data!$H$2:$H$500,"Meeting Scheduled") -> 3 | G32: =COUNTIFS(Clean_Data!$C$2:$C$500,$A32,Clean_Data!$H$2:$H$500,"Engaged") -> 3 | H32: =COUNTIFS(Clean_Data!$C$2:$C$500,$A32,Clean_Data!$H$2:$H$500,"On Hold") -> 0 | I32: =COUNTIFS(Clean_Data!$C$2:$C$500,$A32,Clean_Data!$H$2:$H$500,"Closed") -> 1 | J32: =IF(B32=0,0,G32/B32) -> 0.21428571 | K32: =COUNTIFS(Clean_Data!$C$2:$C$500,$A32,Clean_Data!$N$2:$N$500,"High") -> 1 | L32: =IFERROR(AVERAGEIFS(Clean_Data!$M$2:$M$500,Clean_Data!$C$2:$C$500,$A32,Clean_Data!$H$2:$H$500,"<>Not Started"),0) -> 5.2727273 | M32: =SUMIFS(Clean_Data!$S$2:$S$500,Clean_Data!$C$2:$C$500,$A32) -> 4 | N32: =SUMIFS(Clean_Data!$T$2:$T$500,Clean_Data!$C$2:$C$500,$A32) -> 1 | O32: =COUNTIFS(Clean_Data!$C$2:$C$500,$A32,Clean_Data!$I$2:$I$500,"") -> 2 | P32: =B32-C32 -> 12 | Q32: =D32+E32+F32 -> 8 | R32: =H32+I32 -> 1
A33: South & Central Asia | B33: =COUNTIF(Clean_Data!$C$2:$C$500,$A33) -> 8 | C33: =COUNTIFS(Clean_Data!$C$2:$C$500,$A33,Clean_Data!$H$2:$H$500,"Not Started") -> 1 | D33: =COUNTIFS(Clean_Data!$C$2:$C$500,$A33,Clean_Data!$H$2:$H$500,"Initial Contact") -> 3 | E33: =COUNTIFS(Clean_Data!$C$2:$C$500,$A33,Clean_Data!$H$2:$H$500,"In Discussion") -> 1 | F33: =COUNTIFS(Clean_Data!$C$2:$C$500,$A33,Clean_Data!$H$2:$H$500,"Meeting Scheduled") -> 1 | G33: =COUNTIFS(Clean_Data!$C$2:$C$500,$A33,Clean_Data!$H$2:$H$500,"Engaged") -> 1 | H33: =COUNTIFS(Clean_Data!$C$2:$C$500,$A33,Clean_Data!$H$2:$H$500,"On Hold") -> 1 | I33: =COUNTIFS(Clean_Data!$C$2:$C$500,$A33,Clean_Data!$H$2:$H$500,"Closed") -> 0 | J33: =IF(B33=0,0,G33/B33) -> 0.125 | K33: =COUNTIFS(Clean_Data!$C$2:$C$500,$A33,Clean_Data!$N$2:$N$500,"High") -> 1 | L33: =IFERROR(AVERAGEIFS(Clean_Data!$M$2:$M$500,Clean_Data!$C$2:$C$500,$A33,Clean_Data!$H$2:$H$500,"<>Not Started"),0) -> 5 | M33: =SUMIFS(Clean_Data!$S$2:$S$500,Clean_Data!$C$2:$C$500,$A33) -> 4 | N33: =SUMIFS(Clean_Data!$T$2:$T$500,Clean_Data!$C$2:$C$500,$A33) -> 2 | O33: =COUNTIFS(Clean_Data!$C$2:$C$500,$A33,Clean_Data!$I$2:$I$500,"") -> 0 | P33: =B33-C33 -> 7 | Q33: =D33+E33+F33 -> 5 | R33: =H33+I33 -> 1
A34: Total | B34: =SUM(B28:B33) -> 84 | C34: =SUM(C28:C33) -> 10 | D34: =SUM(D28:D33) -> 15 | E34: =SUM(E28:E33) -> 14 | F34: =SUM(F28:F33) -> 11 | G34: =SUM(G28:G33) -> 19 | H34: =SUM(H28:H33) -> 11 | I34: =SUM(I28:I33) -> 4 | J34: =IF(B34=0,0,G34/B34) -> 0.22619048 | K34: =SUM(K28:K33) -> 17 | L34: =IFERROR(AVERAGEIFS(Clean_Data!$M$2:$M$500,Clean_Data!$H$2:$H$500,"<>Not Started",Clean_Data!$A$2:$A$500,"<>"),0) -> 5.8823529 | M34: =SUM(M28:M33) -> 30 | N34: =SUM(N28:N33) -> 13 | O34: =SUM(O28:O33) -> 8 | P34: =SUM(P28:P33) -> 74 | Q34: =SUM(Q28:Q33) -> 40 | R34: =SUM(R28:R33) -> 15
A37: 4. Owner workload
A38: Outreach Owner | B38: Embassies | C38: Live Pipeline | D38: Overdue Follow-ups | E38: Stale | F38: Avg Days Since Contact | G38: High Engagement
A39: Anita Deshmukh | B39: =COUNTIF(Clean_Data!$I$2:$I$500,$A39) -> 8 | C39: =SUMIFS(Clean_Data!$Q$2:$Q$500,Clean_Data!$I$2:$I$500,$A39) -> 5 | D39: =SUMIFS(Clean_Data!$S$2:$S$500,Clean_Data!$I$2:$I$500,$A39) -> 2 | E39: =SUMIFS(Clean_Data!$T$2:$T$500,Clean_Data!$I$2:$I$500,$A39) -> 1 | F39: =IFERROR(AVERAGEIFS(Clean_Data!$R$2:$R$500,Clean_Data!$I$2:$I$500,$A39),0) -> 93.5 | G39: =COUNTIFS(Clean_Data!$I$2:$I$500,$A39,Clean_Data!$N$2:$N$500,"High") -> 1
A40: Rahul Verma | B40: =COUNTIF(Clean_Data!$I$2:$I$500,$A40) -> 13 | C40: =SUMIFS(Clean_Data!$Q$2:$Q$500,Clean_Data!$I$2:$I$500,$A40) -> 9 | D40: =SUMIFS(Clean_Data!$S$2:$S$500,Clean_Data!$I$2:$I$500,$A40) -> 1 | E40: =SUMIFS(Clean_Data!$T$2:$T$500,Clean_Data!$I$2:$I$500,$A40) -> 0 | F40: =IFERROR(AVERAGEIFS(Clean_Data!$R$2:$R$500,Clean_Data!$I$2:$I$500,$A40),0) -> 89.4 | G40: =COUNTIFS(Clean_Data!$I$2:$I$500,$A40,Clean_Data!$N$2:$N$500,"High") -> 3
A41: Priya Nair | B41: =COUNTIF(Clean_Data!$I$2:$I$500,$A41) -> 14 | C41: =SUMIFS(Clean_Data!$Q$2:$Q$500,Clean_Data!$I$2:$I$500,$A41) -> 11 | D41: =SUMIFS(Clean_Data!$S$2:$S$500,Clean_Data!$I$2:$I$500,$A41) -> 8 | E41: =SUMIFS(Clean_Data!$T$2:$T$500,Clean_Data!$I$2:$I$500,$A41) -> 2 | F41: =IFERROR(AVERAGEIFS(Clean_Data!$R$2:$R$500,Clean_Data!$I$2:$I$500,$A41),0) -> 89.076923 | G41: =COUNTIFS(Clean_Data!$I$2:$I$500,$A41,Clean_Data!$N$2:$N$500,"High") -> 5
A42: Sameer Khan | B42: =COUNTIF(Clean_Data!$I$2:$I$500,$A42) -> 14 | C42: =SUMIFS(Clean_Data!$Q$2:$Q$500,Clean_Data!$I$2:$I$500,$A42) -> 11 | D42: =SUMIFS(Clean_Data!$S$2:$S$500,Clean_Data!$I$2:$I$500,$A42) -> 6 | E42: =SUMIFS(Clean_Data!$T$2:$T$500,Clean_Data!$I$2:$I$500,$A42) -> 3 | F42: =IFERROR(AVERAGEIFS(Clean_Data!$R$2:$R$500,Clean_Data!$I$2:$I$500,$A42),0) -> 116.6 | G42: =COUNTIFS(Clean_Data!$I$2:$I$500,$A42,Clean_Data!$N$2:$N$500,"High") -> 2
A43: Neha Kulkarni | B43: =COUNTIF(Clean_Data!$I$2:$I$500,$A43) -> 14 | C43: =SUMIFS(Clean_Data!$Q$2:$Q$500,Clean_Data!$I$2:$I$500,$A43) -> 9 | D43: =SUMIFS(Clean_Data!$S$2:$S$500,Clean_Data!$I$2:$I$500,$A43) -> 6 | E43: =SUMIFS(Clean_Data!$T$2:$T$500,Clean_Data!$I$2:$I$500,$A43) -> 2 | F43: =IFERROR(AVERAGEIFS(Clean_Data!$R$2:$R$500,Clean_Data!$I$2:$I$500,$A43),0) -> 93.5 | G43: =COUNTIFS(Clean_Data!$I$2:$I$500,$A43,Clean_Data!$N$2:$N$500,"High") -> 4
A44: Arjun Mehta | B44: =COUNTIF(Clean_Data!$I$2:$I$500,$A44) -> 13 | C44: =SUMIFS(Clean_Data!$Q$2:$Q$500,Clean_Data!$I$2:$I$500,$A44) -> 9 | D44: =SUMIFS(Clean_Data!$S$2:$S$500,Clean_Data!$I$2:$I$500,$A44) -> 5 | E44: =SUMIFS(Clean_Data!$T$2:$T$500,Clean_Data!$I$2:$I$500,$A44) -> 4 | F44: =IFERROR(AVERAGEIFS(Clean_Data!$R$2:$R$500,Clean_Data!$I$2:$I$500,$A44),0) -> 82.75 | G44: =COUNTIFS(Clean_Data!$I$2:$I$500,$A44,Clean_Data!$N$2:$N$500,"High") -> 2
A45: Unassigned | B45: =COUNTIFS(Clean_Data!$A$2:$A$500,"<>",Clean_Data!$I$2:$I$500,"") -> 8 | C45: =SUMIFS(Clean_Data!$Q$2:$Q$500,Clean_Data!$A$2:$A$500,"<>",Clean_Data!$I$2:$I$500,"") -> 5 | D45: =SUMIFS(Clean_Data!$S$2:$S$500,Clean_Data!$A$2:$A$500,"<>",Clean_Data!$I$2:$I$500,"") -> 2 | E45: =SUMIFS(Clean_Data!$T$2:$T$500,Clean_Data!$A$2:$A$500,"<>",Clean_Data!$I$2:$I$500,"") -> 1 | F45: =IFERROR(AVERAGEIFS(Clean_Data!$R$2:$R$500,Clean_Data!$A$2:$A$500,"<>",Clean_Data!$I$2:$I$500,""),0) -> 37.4 | G45: =COUNTIFS(Clean_Data!$A$2:$A$500,"<>",Clean_Data!$I$2:$I$500,"",Clean_Data!$N$2:$N$500,"High") -> 0
A46: Total | B46: =SUM(B39:B45) -> 84 | C46: =SUM(C39:C45) -> 59 | D46: =SUM(D39:D45) -> 30 | E46: =SUM(E39:E45) -> 13 | F46: =IFERROR(AVERAGE(Clean_Data!$R$2:$R$500),0) -> 89.542857 | G46: =SUM(G39:G45) -> 17
...

Sheet Clean_Data
A1: Embassy_ID | B1: Embassy (Country) | C1: Region | D1: Contact Person | E1: Designation | F1: Email | G1: Phone | H1: Outreach Status | I1: Outreach Owner | J1: First Contact | K1: Last Contact | L1: Next Follow-up | M1: Interactions | N1: Engagement Level | O1: Channel | P1: Remarks | Q1: Live Pipeline (1/0) | R1: Days Since Last Contact | S1: Follow-up Overdue (1/0) | T1: Stale (1/0) | U1: No Follow-up Date (1/0) | V1: Email Check | W1: Phone Check | X1: Last Contact < First Contact (1/0) | Y1: Future-dated Last Contact (1/0) | Z1: Remark Conflicts Status (1/0) | AA1: Priority Score | AB1: Attention Issues | AD1: Cleaned & de-duplicated dataset. Columns A-P = standardised source data; Q-AB (blue headers) = formulas that drive the Dashboard.
A2: EMB-001 | B2: France | C2: Europe | D2: Mei Schmidt | E2: Counsellor (Public Affairs) | F2: mei.schmidt@france.embassy.example | G2: +91 91399 86987 | H2: Not Started | I2: Neha Kulkarni | M2: 0 | P2: Priority list - Q4 | Q2: =IF(OR(H2="Initial Contact",H2="In Discussion",H2="Meeting Scheduled",H2="Engaged"),1,0) -> 0 | R2: =IF(OR(K2="",K2>Analysis!$B$3),"",Analysis!$B$3-K2) | S2: =IF(AND(Q2=1,L2<>"",L2<Analysis!$B$3),1,0) -> 0 | T2: =IF(Q2=1,IF(R2="",0,IF(R2>Analysis!$B$4,1,0)),0) -> 0 | U2: =IF(AND(Q2=1,L2=""),1,0) -> 0 | V2: =IF(TRIM(F2)="","Missing",IF(IFERROR(FIND(".",F2,FIND("@",F2)),0)>0,"Valid","Invalid")) -> Valid | W2: =IF(TRIM(G2)="","Missing",IF(OR(AND(LEFT(G2,4)="+91 ",LEN(G2)=15),AND(LEFT(G2,7)="+91 11 ",LEN(G2)=16)),"Valid","Invalid")) -> Valid | X2: =IF(AND(J2<>"",K2<>"",K2<J2),1,0) -> 0 | Y2: =IF(AND(K2<>"",K2>Analysis!$B$3),1,0) -> 0 | Z2: =IF(AND(Q2=1,ISNUMBER(SEARCH("declin",P2))),1,0) -> 0 | AA2: =IF(Q2=1,S2*2+T2*2+U2+IF(I2="",1,0)+IF(N2="High",2,IF(N2="Medium",1,0)),0) -> 0 | AB2: =IF(Q2=0,"",TRIM(IF(S2=1,"Follow-up overdue. ","")&IF(T2=1,"No contact "&Analysis!$B$4&"+ days. ","")&IF(U2=1,"No follow-up date. ","")&IF(I2="","No owner. ","")&IF(Z2=1,"Remarks conflict with status. ","")&IF(X2=1,"Date error (last < first). ","")&IF(Y2=1,"Future-dated contact. ","")))
A3: EMB-002 | B3: Germany | C3: Europe | D3: Stefan Haddad | E3: Commercial Counsellor | F3: stefan.haddad@germany.embassy.example | G3: +91 11 8170 7536 | H3: Initial Contact | I3: Priya Nair | J3: 46057 | K3: 46078 | L3: 46132 | M3: 1 | N3: Low | O3: Email | P3: Intro call held | Q3: =IF(OR(H3="Initial Contact",H3="In Discussion",H3="Meeting Scheduled",H3="Engaged"),1,0) -> 1 | R3: =IF(OR(K3="",K3>Analysis!$B$3),"",Analysis!$B$3-K3) -> 222 | S3: =IF(AND(Q3=1,L3<>"",L3<Analysis!$B$3),1,0) -> 1 | T3: =IF(Q3=1,IF(R3="",0,IF(R3>Analysis!$B$4,1,0)),0) -> 1 | U3: =IF(AND(Q3=1,L3=""),1,0) -> 0 | V3: =IF(TRIM(F3)="","Missing",IF(IFERROR(FIND(".",F3,FIND("@",F3)),0)>0,"Valid","Invalid")) -> Valid | W3: =IF(TRIM(G3)="","Missing",IF(OR(AND(LEFT(G3,4)="+91 ",LEN(G3)=15),AND(LEFT(G3,7)="+91 11 ",LEN(G3)=16)),"Valid","Invalid")) -> Valid | X3: =IF(AND(J3<>"",K3<>"",K3<J3),1,0) -> 0 | Y3: =IF(AND(K3<>"",K3>Analysis!$B$3),1,0) -> 0 | Z3: =IF(AND(Q3=1,ISNUMBER(SEARCH("declin",P3))),1,0) -> 0 | AA3: =IF(Q3=1,S3*2+T3*2+U3+IF(I3="",1,0)+IF(N3="High",2,IF(N3="Medium",1,0)),0) -> 4 | AB3: =IF(Q3=0,"",TRIM(IF(S3=1,"Follow-up overdue. ","")&IF(T3=1,"No contact "&Analysis!$B$4&"+ days. ","")&IF(U3=1,"No follow-up date. ","")&IF(I3="","No owner. ","")&IF(Z3=1,"Remarks conflict with status. ","")&IF(X3=1,"Date error (last < first). ","")&IF(Y3=1,"Future-dated contact. ",""))) -> Follow-up overdue. No contact 90+ days.
A4: EMB-003 | B4: Italy | C4: Europe | D4: Kwame Okafor | E4: Counsellor (Public Affairs) | F4: kwame.okafor@italy.embassy.example | G4: +91 11 2698 7168 | H4: On Hold | I4: Neha Kulkarni | J4: 46079 | K4: 46143 | L4: 46257 | M4: 6 | O4: Phone | P4: Awaiting HQ approval | Q4: =IF(OR(H4="Initial Contact",H4="In Discussion",H4="Meeting Scheduled",H4="Engaged"),1,0) -> 0 | R4: =IF(OR(K4="",K4>Analysis!$B$3),"",Analysis!$B$3-K4) -> 157 | S4: =IF(AND(Q4=1,L4<>"",L4<Analysis!$B$3),1,0) -> 0 | T4: =IF(Q4=1,IF(R4="",0,IF(R4>Analysis!$B$4,1,0)),0) -> 0 | U4: =IF(AND(Q4=1,L4=""),1,0) -> 0 | V4: =IF(TRIM(F4)="","Missing",IF(IFERROR(FIND(".",F4,FIND("@",F4)),0)>0,"Valid","Invalid")) -> Valid | W4: =IF(TRIM(G4)="","Missing",IF(OR(AND(LEFT(G4,4)="+91 ",LEN(G4)=15),AND(LEFT(G4,7)="+91 11 ",LEN(G4)=16)),"Valid","Invalid")) -> Valid | X4: =IF(AND(J4<>"",K4<>"",K4<J4),1,0) -> 0 | Y4: =IF(AND(K4<>"",K4>Analysis!$B$3),1,0) -> 0 | Z4: =IF(AND(Q4=1,ISNUMBER(SEARCH("declin",P4))),1,0) -> 0 | AA4: =IF(Q4=1,S4*2+T4*2+U4+IF(I4="",1,0)+IF(N4="High",2,IF(N4="Medium",1,0)),0) -> 0 | AB4: =IF(Q4=0,"",TRIM(IF(S4=1,"Follow-up overdue. ","")&IF(T4=1,"No contact "&Analysis!$B$4&"+ days. ","")&IF(U4=1,"No follow-up date. ","")&IF(I4="","No owner. ","")&IF(Z4=1,"Remarks conflict with status. ","")&IF(X4=1,"Date error (last < first). ","")&IF(Y4=1,"Future-dated contact. ","")))
A5: EMB-004 | B5: Spain | C5: Europe | D5: Leila Bergstrom | E5: Protocol Officer | F5: leila.bergstrom@spain.embassy.example | G5: +91 11 3731 7784 | H5: Engaged | I5: Sameer Khan | J5: 46233 | K5: 46248 | L5: 46287 | M5: 19 | N5: High | O5: Phone | P5: Regular quarterly touchpoints | Q5: =IF(OR(H5="Initial Contact",H5="In Discussion",H5="Meeting Scheduled",H5="Engaged"),1,0) -> 1 | R5: =IF(OR(K5="",K5>Analysis!$B$3),"",Analysis!$B$3-K5) -> 52 | S5: =IF(AND(Q5=1,L5<>"",L5<Analysis!$B$3),1,0) -> 1 | T5: =IF(Q5=1,IF(R5="",0,IF(R5>Analysis!$B$4,1,0)),0) -> 0 | U5: =IF(AND(Q5=1,L5=""),1,0) -> 0 | V5: =IF(TRIM(F5)="","Missing",IF(IFERROR(FIND(".",F5,FIND("@",F5)),0)>0,"Valid","Invalid")) -> Valid | W5: =IF(TRIM(G5)="","Missing",IF(OR(AND(LEFT(G5,4)="+91 ",LEN(G5)=15),AND(LEFT(G5,7)="+91 11 ",LEN(G5)=16)),"Valid","Invalid")) -> Valid | X5: =IF(AND(J5<>"",K5<>"",K5<J5),1,0) -> 0 | Y5: =IF(AND(K5<>"",K5>Analysis!$B$3),1,0) -> 0 | Z5: =IF(AND(Q5=1,ISNUMBER(SEARCH("declin",P5))),1,0) -> 0 | AA5: =IF(Q5=1,S5*2+T5*2+U5+IF(I5="",1,0)+IF(N5="High",2,IF(N5="Medium",1,0)),0) -> 4 | AB5: =IF(Q5=0,"",TRIM(IF(S5=1,"Follow-up overdue. ","")&IF(T5=1,"No contact "&Analysis!$B$4&"+ days. ","")&IF(U5=1,"No follow-up date. ","")&IF(I5="","No owner. ","")&IF(Z5=1,"Remarks conflict with status. ","")&IF(X5=1,"Date error (last < first). ","")&IF(Y5=1,"Future-dated contact. ",""))) -> Follow-up overdue.
A6: EMB-005 | B6: Portugal | C6: Europe | D6: Omar Khalil | E6: Counsellor (Public Affairs) | F6: omar.khalil@portugal.embassy.example | G6: +91 97876 80457 | H6: In Discussion | I6: Anita Deshmukh | J6: 46199 | K6: 46270 | L6: 46295 | M6: 8 | N6: Low | O6: Official Letter | P6: Positive response | Q6: =IF(OR(H6="Initial Contact",H6="In Discussion",H6="Meeting Scheduled",H6="Engaged"),1,0) -> 1 | R6: =IF(OR(K6="",K6>Analysis!$B$3),"",Analysis!$B$3-K6) -> 30 | S6: =IF(AND(Q6=1,L6<>"",L6<Analysis!$B$3),1,0) -> 1 | T6: =IF(Q6=1,IF(R6="",0,IF(R6>Analysis!$B$4,1,0)),0) -> 0 | U6: =IF(AND(Q6=1,L6=""),1,0) -> 0 | V6: =IF(TRIM(F6)="","Missing",IF(IFERROR(FIND(".",F6,FIND("@",F6)),0)>0,"Valid","Invalid")) -> Valid | W6: =IF(TRIM(G6)="","Missing",IF(OR(AND(LEFT(G6,4)="+91 ",LEN(G6)=15),AND(LEFT(G6,7)="+91 11 ",LEN(G6)=16)),"Valid","Invalid")) -> Valid | X6: =IF(AND(J6<>"",K6<>"",K6<J6),1,0) -> 0 | Y6: =IF(AND(K6<>"",K6>Analysis!$B$3),1,0) -> 0 | Z6: =IF(AND(Q6=1,ISNUMBER(SEARCH("declin",P6))),1,0) -> 0 | AA6: =IF(Q6=1,S6*2+T6*2+U6+IF(I6="",1,0)+IF(N6="High",2,IF(N6="Medium",1,0)),0) -> 2 | AB6: =IF(Q6=0,"",TRIM(IF(S6=1,"Follow-up overdue. ","")&IF(T6=1,"No contact "&Analysis!$B$4&"+ days. ","")&IF(U6=1,"No follow-up date. ","")&IF(I6="","No owner. ","")&IF(Z6=1,"Remarks conflict with status. ","")&IF(X6=1,"Date error (last < first). ","")&IF(Y6=1,"Future-dated contact. ",""))) -> Follow-up overdue.
A7: EMB-006 | B7: Netherlands | C7: Europe | D7: Carla Alvarez | E7: Counsellor (Public Affairs) | F7: carla.alvarez@netherlands.embassy.example | G7: +91 11 8193 3190 | H7: Not Started | I7: Neha Kulkarni | K7: 46249 | M7: 2 | P7: Contact details to be verified | Q7: =IF(OR(H7="Initial Contact",H7="In Discussion",H7="Meeting Scheduled",H7="Engaged"),1,0) -> 0 | R7: =IF(OR(K7="",K7>Analysis!$B$3),"",Analysis!$B$3-K7) -> 51 | S7: =IF(AND(Q7=1,L7<>"",L7<Analysis!$B$3),1,0) -> 0 | T7: =IF(Q7=1,IF(R7="",0,IF(R7>Analysis!$B$4,1,0)),0) -> 0 | U7: =IF(AND(Q7=1,L7=""),1,0) -> 0 | V7: =IF(TRIM(F7)="","Missing",IF(IFERROR(FIND(".",F7,FIND("@",F7)),0)>0,"Valid","Invalid")) -> Valid | W7: =IF(TRIM(G7)="","Missing",IF(OR(AND(LEFT(G7,4)="+91 ",LEN(G7)=15),AND(LEFT(G7,7)="+91 11 ",LEN(G7)=16)),"Valid","Invalid")) -> Valid | X7: =IF(AND(J7<>"",K7<>"",K7<J7),1,0) -> 0 | Y7: =IF(AND(K7<>"",K7>Analysis!$B$3),1,0) -> 0 | Z7: =IF(AND(Q7=1,ISNUMBER(SEARCH("declin",P7))),1,0) -> 0 | AA7: =IF(Q7=1,S7*2+T7*2+U7+IF(I7="",1,0)+IF(N7="High",2,IF(N7="Medium",1,0)),0) -> 0 | AB7: =IF(Q7=0,"",TRIM(IF(S7=1,"Follow-up overdue. ","")&IF(T7=1,"No contact "&Analysis!$B$4&"+ days. ","")&IF(U7=1,"No follow-up date. ","")&IF(I7="","No owner. ","")&IF(Z7=1,"Remarks conflict with status. ","")&IF(X7=1,"Date error (last < first). ","")&IF(Y7=1,"Future-dated contact. ","")))
A8: EMB-007 | B8: Belgium | C8: Europe | D8: Amara Okafor | E8: Protocol Officer | F8: amara.okafor@belgium.embassy.example | G8: +91 11 4997 2837 | H8: Engaged | I8: Rahul Verma | J8: 45758 | K8: 46294 | L8: 46316 | N8: Medium | O8: Event | P8: Regular quarterly touchpoints | Q8: =IF(OR(H8="Initial Contact",H8="In Discussion",H8="Meeting Scheduled",H8="Engaged"),1,0) -> 1 | R8: =IF(OR(K8="",K8>Analysis!$B$3),"",Analysis!$B$3-K8) -> 6 | S8: =IF(AND(Q8=1,L8<>"",L8<Analysis!$B$3),1,0) -> 0 | T8: =IF(Q8=1,IF(R8="",0,IF(R8>Analysis!$B$4,1,0)),0) -> 0 | U8: =IF(AND(Q8=1,L8=""),1,0) -> 0 | V8: =IF(TRIM(F8)="","Missing",IF(IFERROR(FIND(".",F8,FIND("@",F8)),0)>0,"Valid","Invalid")) -> Valid | W8: =IF(TRIM(G8)="","Missing",IF(OR(AND(LEFT(G8,4)="+91 ",LEN(G8)=15),AND(LEFT(G8,7)="+91 11 ",LEN(G8)=16)),"Valid","Invalid")) -> Valid | X8: =IF(AND(J8<>"",K8<>"",K8<J8),1,0) -> 0 | Y8: =IF(AND(K8<>"",K8>Analysis!$B$3),1,0) -> 0 | Z8: =IF(AND(Q8=1,ISNUMBER(SEARCH("declin",P8))),1,0) -> 0 | AA8: =IF(Q8=1,S8*2+T8*2+U8+IF(I8="",1,0)+IF(N8="High",2,IF(N8="Medium",1,0)),0) -> 1 | AB8: =IF(Q8=0,"",TRIM(IF(S8=1,"Follow-up overdue. ","")&IF(T8=1,"No contact "&Analysis!$B$4&"+ days. ","")&IF(U8=1,"No follow-up date. ","")&IF(I8="","No owner. ","")&IF(Z8=1,"Remarks conflict with status. ","")&IF(X8=1,"Date error (last < first). ","")&IF(Y8=1,"Future-dated contact. ","")))
A9: EMB-008 | B9: Switzerland | C9: Europe | D9: Elena Rossi | E9: Protocol Officer | F9: elena.rossi@switzerland.embassy.example | G9: +91 11 4475 1779 | H9: Meeting Scheduled | I9: Rahul Verma | J9: 46204 | K9: 46280 | O9: Official Letter | P9: Meeting with Ambassador pending | Q9: =IF(OR(H9="Initial Contact",H9="In Discussion",H9="Meeting Scheduled",H9="Engaged"),1,0) -> 1 | R9: =IF(OR(K9="",K9>Analysis!$B$3),"",Analysis!$B$3-K9) -> 20 | S9: =IF(AND(Q9=1,L9<>"",L9<Analysis!$B$3),1,0) -> 0 | T9: =IF(Q9=1,IF(R9="",0,IF(R9>Analysis!$B$4,1,0)),0) -> 0 | U9: =IF(AND(Q9=1,L9=""),1,0) -> 1 | V9: =IF(TRIM(F9)="","Missing",IF(IFERROR(FIND(".",F9,FIND("@",F9)),0)>0,"Valid","Invalid")) -> Valid | W9: =IF(TRIM(G9)="","Missing",IF(OR(AND(LEFT(G9,4)="+91 ",LEN(G9)=15),AND(LEFT(G9,7)="+91 11 ",LEN(G9)=16)),"Valid","Invalid")) -> Valid | X9: =IF(AND(J9<>"",K9<>"",K9<J9),1,0) -> 0 | Y9: =IF(AND(K9<>"",K9>Analysis!$B$3),1,0) -> 0 | Z9: =IF(AND(Q9=1,ISNUMBER(SEARCH("declin",P9))),1,0) -> 0 | AA9: =IF(Q9=1,S9*2+T9*2+U9+IF(I9="",1,0)+IF(N9="High",2,IF(N9="Medium",1,0)),0) -> 1 | AB9: =IF(Q9=0,"",TRIM(IF(S9=1,"Follow-up overdue. ","")&IF(T9=1,"No contact "&Analysis!$B$4&"+ days. ","")&IF(U9=1,"No follow-up date. ","")&IF(I9="","No owner. ","")&IF(Z9=1,"Remarks conflict with status. ","")&IF(X9=1,"Date error (last < first). ","")&IF(Y9=1,"Future-dated contact. ",""))) -> No follow-up date.
A10: EMB-009 | B10: Austria | C10: Europe | D10: Amara Petrov | E10: Second Secretary | G10: +91 11 7028 3 | H10: Not Started | M10: 0 | P10: Priority list - Q4 | Q10: =IF(OR(H10="Initial Contact",H10="In Discussion",H10="Meeting Scheduled",H10="Engaged"),1,0) -> 0 | R10: =IF(OR(K10="",K10>Analysis!$B$3),"",Analysis!$B$3-K10) | S10: =IF(AND(Q10=1,L10<>"",L10<Analysis!$B$3),1,0) -> 0 | T10: =IF(Q10=1,IF(R10="",0,IF(R10>Analysis!$B$4,1,0)),0) -> 0 | U10: =IF(AND(Q10=1,L10=""),1,0) -> 0 | V10: =IF(TRIM(F10)="","Missing",IF(IFERROR(FIND(".",F10,FIND("@",F10)),0)>0,"Valid","Invalid")) -> Missing | W10: =IF(TRIM(G10)="","Missing",IF(OR(AND(LEFT(G10,4)="+91 ",LEN(G10)=15),AND(LEFT(G10,7)="+91 11 ",LEN(G10)=16)),"Valid","Invalid")) -> Invalid | X10: =IF(AND(J10<>"",K10<>"",K10<J10),1,0) -> 0 | Y10: =IF(AND(K10<>"",K10>Analysis!$B$3),1,0) -> 0 | Z10: =IF(AND(Q10=1,ISNUMBER(SEARCH("declin",P10))),1,0) -> 0 | AA10: =IF(Q10=1,S10*2+T10*2+U10+IF(I10="",1,0)+IF(N10="High",2,IF(N10="Medium",1,0)),0) -> 0 | AB10: =IF(Q10=0,"",TRIM(IF(S10=1,"Follow-up overdue. ","")&IF(T10=1,"No contact "&Analysis!$B$4&"+ days. ","")&IF(U10=1,"No follow-up date. ","")&IF(I10="","No owner. ","")&IF(Z10=1,"Remarks conflict with status. ","")&IF(X10=1,"Date error (last < first). ","")&IF(Y10=1,"Future-dated contact. ","")))
A11: EMB-010 | B11: Sweden | C11: Europe | D11: Joao Garcia | E11: Commercial Counsellor | F11: joao.garcia@sweden.embassy.example | G11: +91 96425 24776 | H11: Initial Contact | I11: Sameer Khan | J11: 46005 | M11: 2 | N11: Medium | O11: Event | P11: Awaiting acknowledgement | Q11: =IF(OR(H11="Initial Contact",H11="In Discussion",H11="Meeting Scheduled",H11="Engaged"),1,0) -> 1 | R11: =IF(OR(K11="",K11>Analysis!$B$3),"",Analysis!$B$3-K11) | S11: =IF(AND(Q11=1,L11<>"",L11<Analysis!$B$3),1,0) -> 0 | T11: =IF(Q11=1,IF(R11="",0,IF(R11>Analysis!$B$4,1,0)),0) -> 0 | U11: =IF(AND(Q11=1,L11=""),1,0) -> 1 | V11: =IF(TRIM(F11)="","Missing",IF(IFERROR(FIND(".",F11,FIND("@",F11)),0)>0,"Valid","Invalid")) -> Valid | W11: =IF(TRIM(G11)="","Missing",IF(OR(AND(LEFT(G11,4)="+91 ",LEN(G11)=15),AND(LEFT(G11,7)="+91 11 ",LEN(G11)=16)),"Valid","Invalid")) -> Valid | X11: =IF(AND(J11<>"",K11<>"",K11<J11),1,0) -> 0 | Y11: =IF(AND(K11<>"",K11>Analysis!$B$3),1,0) -> 0 | Z11: =IF(AND(Q11=1,ISNUMBER(SEARCH("declin",P11))),1,0) -> 0 | AA11: =IF(Q11=1,S11*2+T11*2+U11+IF(I11="",1,0)+IF(N11="High",2,IF(N11="Medium",1,0)),0) -> 2 | AB11: =IF(Q11=0,"",TRIM(IF(S11=1,"Follow-up overdue. ","")&IF(T11=1,"No contact "&Analysis!$B$4&"+ days. ","")&IF(U11=1,"No follow-up date. ","")&IF(I11="","No owner. ","")&IF(Z11=1,"Remarks conflict with status. ","")&IF(X11=1,"Date error (last < first). ","")&IF(Y11=1,"Future-dated contact. ",""))) -> No follow-up date.
A12: EMB-011 | B12: Norway | C12: Europe | D12: Diego Mensah | E12: Second Secretary | F12: diego.mensah@norway.embassy.example | G12: +91 95258 98319 | H12: On Hold | I12: Priya Nair | J12: 45891 | K12: 46233 | L12: 46310 | M12: 2 | N12: Low | O12: Email | P12: Paused - elections | Q12: =IF(OR(H12="Initial Contact",H12="In Discussion",H12="Meeting Scheduled",H12="Engaged"),1,0) -> 0 | R12: =IF(OR(K12="",K12>Analysis!$B$3),"",Analysis!$B$3-K12) -> 67 | S12: =IF(AND(Q12=1,L12<>"",L12<Analysis!$B$3),1,0) -> 0 | T12: =IF(Q12=1,IF(R12="",0,IF(R12>Analysis!$B$4,1,0)),0) -> 0 | U12: =IF(AND(Q12=1,L12=""),1,0) -> 0 | V12: =IF(TRIM(F12)="","Missing",IF(IFERROR(FIND(".",F12,FIND("@",F12)),0)>0,"Valid","Invalid")) -> Valid | W12: =IF(TRIM(G12)="","Missing",IF(OR(AND(LEFT(G12,4)="+91 ",LEN(G12)=15),AND(LEFT(G12,7)="+91 11 ",LEN(G12)=16)),"Valid","Invalid")) -> Valid | X12: =IF(AND(J12<>"",K12<>"",K12<J12),1,0) -> 0 | Y12: =IF(AND(K12<>"",K12>Analysis!$B$3),1,0) -> 0 | Z12: =IF(AND(Q12=1,ISNUMBER(SEARCH("declin",P12))),1,0) -> 0 | AA12: =IF(Q12=1,S12*2+T12*2+U12+IF(I12="",1,0)+IF(N12="High",2,IF(N12="Medium",1,0)),0) -> 0 | AB12: =IF(Q12=0,"",TRIM(IF(S12=1,"Follow-up overdue. ","")&IF(T12=1,"No contact "&Analysis!$B$4&"+ days. ","")&IF(U12=1,"No follow-up date. ","")&IF(I12="","No owner. ","")&IF(Z12=1,"Remarks conflict with status. ","")&IF(X12=1,"Date error (last < first). ","")&IF(Y12=1,"Future-dated contact. ","")))
